Workbook

Sheet Crude Inventory (Live Formulas)
A1: CRUDE INVENTORY BY TANK — MPC Carson Refinery | AORA Mass Balance System | Volumes in Barrels (MB)
A2: Recon Date: 2026-01-01 | Recon Status: Preliminary | Click any formula cell → formula shown in fx bar above
A3: ■ GREEN = SUM formula (=E[r1]+E[r2]+...) ■ YELLOW = IF% formula (=IF(total=0,0,this_row/total)) ■ ORANGE = Grand Total SUM (all crude rows across all tanks)
A4: # | B4: Tank | C4: Crude Code | D4: Crude Description | E4: Opening Volume (MB) | F4: Opening % | G4: Closing Volume (MB) | H4: Closing %
A5: Tank: TK13 (2 crude types)
B6: TK13 | C6: ANS | D6: Alaskan North Slope | E6: 336048.88 | F6: =IF((E6+E7)=0,0,E6/(E6+E7)) | G6: 295974.91 | H6: =IF((G6+G7)=0,0,G6/(G6+G7))
B7: TK13 | C7: MED | D7: Medanito | E7: 58004.686 | F7: =IF((E6+E7)=0,0,E7/(E6+E7)) | G7: 41600.582 | H7: =IF((G6+G7)=0,0,G7/(G6+G7))
B8: TK13 | C8: Total | D8: Total for TK13 | E8: =E6+E7 | F8: 1 | G8: =G6+G7 | H8: 1
A9: Tank: TK16 (4 crude types)
B10: TK16 | C10: ANS | D10: Alaskan North Slope | E10: 4576.383 | F10: =IF((E10+E11+E12+E13)=0,0,E10/(E10+E11+E12+E13)) | G10: 3145.954 | H10: =IF((G10+G11+G12+G13)=0,0,G10/(G10+G11+G12+G13))
B11: TK16 | C11: IRA | D11: Iracema | E11: 4681.124 | F11: =IF((E10+E11+E12+E13)=0,0,E11/(E10+E11+E12+E13)) | G11: 3217.957 | H11: =IF((G10+G11+G12+G13)=0,0,G11/(G10+G11+G12+G13))
B12: TK16 | C12: LUL | D12: Tupi (Lula) | E12: 169.197 | F12: =IF((E10+E11+E12+E13)=0,0,E12/(E10+E11+E12+E13)) | G12: 116.312 | H12: =IF((G10+G11+G12+G13)=0,0,G12/(G10+G11+G12+G13))
B13: TK16 | C13: MRO | D13: Mero | E13: 71143.416 | F13: =IF((E10+E11+E12+E13)=0,0,E13/(E10+E11+E12+E13)) | G13: 48906.297 | H13: =IF((G10+G11+G12+G13)=0,0,G13/(G10+G11+G12+G13))
B14: TK16 | C14: Total | D14: Total for TK16 | E14: =E10+E11+E12+E13 | F14: 1 | G14: =G10+G11+G12+G13 | H14: 1
A15: Tank: TK17 (4 crude types)
B16: TK17 | C16: ANS | D16: Alaskan North Slope | E16: 4694.293 | F16: =IF((E16+E17+E18+E19)=0,0,E16/(E16+E17+E18+E19)) | G16: 3284.006 | H16: =IF((G16+G17+G18+G19)=0,0,G16/(G16+G17+G18+G19))
B17: TK17 | C17: IRA | D17: Iracema | E17: 5012.136 | F17: =IF((E16+E17+E18+E19)=0,0,E17/(E16+E17+E18+E19)) | G17: 3506.361 | H17: =IF((G16+G17+G18+G19)=0,0,G17/(G16+G17+G18+G19))
B18: TK17 | C18: LUL | D18: Tupi (Lula) | E18: 187.446 | F18: =IF((E16+E17+E18+E19)=0,0,E18/(E16+E17+E18+E19)) | G18: 131.132 | H18: =IF((G16+G17+G18+G19)=0,0,G18/(G16+G17+G18+G19))
B19: TK17 | C19: MRO | D19: Mero | E19: 71604.275 | F19: =IF((E16+E17+E18+E19)=0,0,E19/(E16+E17+E18+E19)) | G19: 50092.5 | H19: =IF((G16+G17+G18+G19)=0,0,G19/(G16+G17+G18+G19))
B20: TK17 | C20: Total | D20: Total for TK17 | E20: =E16+E17+E18+E19 | F20: 1 | G20: =G16+G17+G18+G19 | H20: 1
A21: Tank: TK18 (3 crude types)
B22: TK18 | C22: IRA | D22: Iracema | E22: 4265.424 | F22: =IF((E22+E23+E24)=0,0,E22/(E22+E23+E24)) | G22: 4265.424 | H22: =IF((G22+G23+G24)=0,0,G22/(G22+G23+G24))
B23: TK18 | C23: LUL | D23: Tupi (Lula) | E23: 25314.511 | F23: =IF((E22+E23+E24)=0,0,E23/(E22+E23+E24)) | G23: 25314.511 | H23: =IF((G22+G23+G24)=0,0,G23/(G22+G23+G24))
B24: TK18 | C24: MRO | D24: Mero | E24: 38232.845 | F24: =IF((E22+E23+E24)=0,0,E24/(E22+E23+E24)) | G24: 38232.845 | H24: =IF((G22+G23+G24)=0,0,G24/(G22+G23+G24))
B25: TK18 | C25: Total | D25: Total for TK18 | E25: =E22+E23+E24 | F25: 1 | G25: =G22+G23+G24 | H25: 1
A26: Tank: TK2 (1 crude type)
B27: TK2 | C27: Acc_DomesticCrude | D27: Domestic Crude | E27: 27003.49 | F27: =IF((E27)=0,0,E27/(E27)) | G27: 27990.33 | H27: =IF((G27)=0,0,G27/(G27))
B28: TK2 | C28: Total | D28: Total for TK2 | E28: =E27 | F28: 1 | G28: =G27 | H28: 1
A29: Tank: TK27 (4 crude types)
B30: TK27 | C30: 166 | D30: Alkylate | E30: 5060.772 | F30: =IF((E30+E31+E32+E33)=0,0,E30/(E30+E31+E32+E33)) | G30: 3906.274 | H30: =IF((G30+G31+G32+G33)=0,0,G30/(G30+G31+G32+G33))
B31: TK27 | C31: 544 | D31: Alkylate - Purchased | E31: 16.869 | F31: =IF((E30+E31+E32+E33)=0,0,E31/(E30+E31+E32+E33)) | G31: 13.021 | H31: =IF((G30+G31+G32+G33)=0,0,G31/(G30+G31+G32+G33))
B32: TK27 | C32: 59B | D32: Alkylate - Transferred | E32: 591.361 | F32: =IF((E30+E31+E32+E33)=0,0,E32/(E30+E31+E32+E33)) | G32: 456.455 | H32: =IF((G30+G31+G32+G33)=0,0,G32/(G30+G31+G32+G33))
B33: TK27 | C33: RNC | D33: Renewable Naphtha Consumption | E33: 3703.735 | F33: =IF((E30+E31+E32+E33)=0,0,E33/(E30+E31+E32+E33)) | G33: 2858.814 | H33: =IF((G30+G31+G32+G33)=0,0,G33/(G30+G31+G32+G33))
B34: TK27 | C34: Total | D34: Total for TK27 | E34: =E30+E31+E32+E33 | F34: 1 | G34: =G30+G31+G32+G33 | H34: 1
A35: Tank: TK28 (4 crude types)
B36: TK28 | C36: 166 | D36: Alkylate | E36: 5070.567 | F36: =IF((E36+E37+E38+E39)=0,0,E36/(E36+E37+E38+E39)) | G36: 3903.051 | H36: =IF((G36+G37+G38+G39)=0,0,G36/(G36+G37+G38+G39))
B37: TK28 | C37: 544 | D37: Alkylate - Purchased | E37: 16.914 | F37: =IF((E36+E37+E38+E39)=0,0,E37/(E36+E37+E38+E39)) | G37: 13.02 | H37: =IF((G36+G37+G38+G39)=0,0,G37/(G36+G37+G38+G39))
B38: TK28 | C38: 59B | D38: Alkylate - Transferred | E38: 595.763 | F38: =IF((E36+E37+E38+E39)=0,0,E38/(E36+E37+E38+E39)) | G38: 458.587 | H38: =IF((G36+G37+G38+G39)=0,0,G38/(G36+G37+G38+G39))
B39: TK28 | C39: RNC | D39: Renewable Naphtha Consumption | E39: 3713.655 | F39: =IF((E36+E37+E38+E39)=0,0,E39/(E36+E37+E38+E39)) | G39: 2858.572 | H39: =IF((G36+G37+G38+G39)=0,0,G39/(G36+G37+G38+G39))
B40: TK28 | C40: Total | D40: Total for TK28 | E40: =E36+E37+E38+E39 | F40: 1 | G40: =G36+G37+G38+G39 | H40: 1
...

Sheet KPI-Table-Formula Reference
A1: CRUDE INVENTORY BY TANK — KPI · TABLE · FORMULA REFERENCE | Click formula cell → see in fx bar
A2: Legend: ■ GREEN = SUM formula ■ YELLOW = IF-based % share formula ■ ORANGE = Grand Total SUM across all tanks ■ GREY = Literal value (1 = 100%)
A3: # | B3: Tank (Table) | C3: Crude Code | D3: Crude Description | E3: KPI Name | F3: KPI Col | G3: Formula (Live — click to see in fx bar) | H3: Formula Type | I3: Formula Logic
A4: 1 | B4: TK13 | C4: ANS | D4: Alaskan North Slope | E4: Opening Volume (MB) | F4: E | G4: ='Crude Inventory (Live Formulas)'!E6 | H4: Raw Value (cross-ref) | I4: Raw measured volume sourced directly from AORA Mass Balance System
E5: Opening % (share) | F5: F | G5: =IF(('Crude Inventory (Live Formulas)'!E6+E7)=0,0,'Crude Inventory (Live Formulas)'!E6/('Crude Inventory (Live Formulas)'!E6+E7)) | H5: IF / Division | I5: Crude's share of tank total opening vol. =0 if tank empty.
E6: Closing Volume (MB) | F6: G | G6: ='Crude Inventory (Live Formulas)'!G6 | H6: Raw Value (cross-ref) | I6: Raw measured volume sourced directly from AORA Mass Balance System
E7: Closing % (share) | F7: H | G7: =IF(('Crude Inventory (Live Formulas)'!G6+G7)=0,0,'Crude Inventory (Live Formulas)'!G6/('Crude Inventory (Live Formulas)'!G6+G7)) | H7: IF / Division | I7: Crude's share of tank total closing vol. =0 if tank empty.
A8: 2 | B8: TK13 | C8: MED | D8: Medanito | E8: Opening Volume (MB) | F8: E | G8: ='Crude Inventory (Live Formulas)'!E7 | H8: Raw Value (cross-ref) | I8: Raw measured volume sourced directly from AORA Mass Balance System
E9: Opening % (share) | F9: F | G9: =IF(('Crude Inventory (Live Formulas)'!E6+E7)=0,0,'Crude Inventory (Live Formulas)'!E7/('Crude Inventory (Live Formulas)'!E6+E7)) | H9: IF / Division | I9: Crude's share of tank total opening vol. =0 if tank empty.
E10: Closing Volume (MB) | F10: G | G10: ='Crude Inventory (Live Formulas)'!G7 | H10: Raw Value (cross-ref) | I10: Raw measured volume sourced directly from AORA Mass Balance System
E11: Closing % (share) | F11: H | G11: =IF(('Crude Inventory (Live Formulas)'!G6+G7)=0,0,'Crude Inventory (Live Formulas)'!G7/('Crude Inventory (Live Formulas)'!G6+G7)) | H11: IF / Division | I11: Crude's share of tank total closing vol. =0 if tank empty.
A12: 3 | B12: TK13 | C12: TOTAL | D12: Total for TK13 | E12: Opening Volume Total (MB) | F12: E | G12: ='Crude Inventory (Live Formulas)'!E6+E7 | H12: SUM | I12: Sum of all crude volumes in this tank group
A13: 4 | B13: TK16 | C13: ANS | D13: Alaskan North Slope | E13: Opening Volume (MB) | F13: E | G13: ='Crude Inventory (Live Formulas)'!E10 | H13: Raw Value (cross-ref) | I13: Raw measured volume sourced directly from AORA Mass Balance System
E14: Opening % (share) | F14: F | G14: =IF(('Crude Inventory (Live Formulas)'!E10+E11+E12+E13)=0,0,'Crude Inventory (Live Formulas)'!E10/('Crude Inventory (Live Formulas)'!E10+E11+E12+E13)) | H14: IF / Division | I14: Crude's share of tank total opening vol. =0 if tank empty.
E15: Closing Volume (MB) | F15: G | G15: ='Crude Inventory (Live Formulas)'!G10 | H15: Raw Value (cross-ref) | I15: Raw measured volume sourced directly from AORA Mass Balance System
E16: Closing % (share) | F16: H | G16: =IF(('Crude Inventory (Live Formulas)'!G10+G11+G12+G13)=0,0,'Crude Inventory (Live Formulas)'!G10/('Crude Inventory (Live Formulas)'!G10+G11+G12+G13)) | H16: IF / Division | I16: Crude's share of tank total closing vol. =0 if tank empty.
A17: 5 | B17: TK16 | C17: IRA | D17: Iracema | E17: Opening Volume (MB) | F17: E | G17: ='Crude Inventory (Live Formulas)'!E11 | H17: Raw Value (cross-ref) | I17: Raw measured volume sourced directly from AORA Mass Balance System
E18: Opening % (share) | F18: F | G18: =IF(('Crude Inventory (Live Formulas)'!E10+E11+E12+E13)=0,0,'Crude Inventory (Live Formulas)'!E11/('Crude Inventory (Live Formulas)'!E10+E11+E12+E13)) | H18: IF / Division | I18: Crude's share of tank total opening vol. =0 if tank empty.
E19: Closing Volume (MB) | F19: G | G19: ='Crude Inventory (Live Formulas)'!G11 | H19: Raw Value (cross-ref) | I19: Raw measured volume sourced directly from AORA Mass Balance System
E20: Closing % (share) | F20: H | G20: =IF(('Crude Inventory (Live Formulas)'!G10+G11+G12+G13)=0,0,'Crude Inventory (Live Formulas)'!G11/('Crude Inventory (Live Formulas)'!G10+G11+G12+G13)) | H20: IF / Division | I20: Crude's share of tank total closing vol. =0 if tank empty.
A21: 6 | B21: TK16 | C21: LUL | D21: Tupi (Lula) | E21: Opening Volume (MB) | F21: E | G21: ='Crude Inventory (Live Formulas)'!E12 | H21: Raw Value (cross-ref) | I21: Raw measured volume sourced directly from AORA Mass Balance System
E22: Opening % (share) | F22: F | G22: =IF(('Crude Inventory (Live Formulas)'!E10+E11+E12+E13)=0,0,'Crude Inventory (Live Formulas)'!E12/('Crude Inventory (Live Formulas)'!E10+E11+E12+E13)) | H22: IF / Division | I22: Crude's share of tank total opening vol. =0 if tank empty.
E23: Closing Volume (MB) | F23: G | G23: ='Crude Inventory (Live Formulas)'!G12 | H23: Raw Value (cross-ref) | I23: Raw measured volume sourced directly from AORA Mass Balance System
E24: Closing % (share) | F24: H | G24: =IF(('Crude Inventory (Live Formulas)'!G10+G11+G12+G13)=0,0,'Crude Inventory (Live Formulas)'!G12/('Crude Inventory (Live Formulas)'!G10+G11+G12+G13)) | H24: IF / Division | I24: Crude's share of tank total closing vol. =0 if tank empty.
A25: 7 | B25: TK16 | C25: MRO | D25: Mero | E25: Opening Volume (MB) | F25: E | G25: ='Crude Inventory (Live Formulas)'!E13 | H25: Raw Value (cross-ref) | I25: Raw measured volume sourced directly from AORA Mass Balance System
E26: Opening % (share) | F26: F | G26: =IF(('Crude Inventory (Live Formulas)'!E10+E11+E12+E13)=0,0,'Crude Inventory (Live Formulas)'!E13/('Crude Inventory (Live Formulas)'!E10+E11+E12+E13)) | H26: IF / Division | I26: Crude's share of tank total opening vol. =0 if tank empty.
E27: Closing Volume (MB) | F27: G | G27: ='Crude Inventory (Live Formulas)'!G13 | H27: Raw Value (cross-ref) | I27: Raw measured volume sourced directly from AORA Mass Balance System
E28: Closing % (share) | F28: H | G28: =IF(('Crude Inventory (Live Formulas)'!G10+G11+G12+G13)=0,0,'Crude Inventory (Live Formulas)'!G13/('Crude Inventory (Live Formulas)'!G10+G11+G12+G13)) | H28: IF / Division | I28: Crude's share of tank total closing vol. =0 if tank empty.
A29: 8 | B29: TK16 | C29: TOTAL | D29: Total for TK16 | E29: Opening Volume Total (MB) | F29: E | G29: ='Crude Inventory (Live Formulas)'!E10+E11+E12+E13 | H29: SUM | I29: Sum of all crude volumes in this tank group
A30: 9 | B30: TK17 | C30: ANS | D30: Alaskan North Slope | E30: Opening Volume (MB) | F30: E | G30: ='Crude Inventory (Live Formulas)'!E16 | H30: Raw Value (cross-ref) | I30: Raw measured volume sourced directly from AORA Mass Balance System
E31: Opening % (share) | F31: F | G31: =IF(('Crude Inventory (Live Formulas)'!E16+E17+E18+E19)=0,0,'Crude Inventory (Live Formulas)'!E16/('Crude Inventory (Live Formulas)'!E16+E17+E18+E19)) | H31: IF / Division | I31: Crude's share of tank total opening vol. =0 if tank empty.
E32: Closing Volume (MB) | F32: G | G32: ='Crude Inventory (Live Formulas)'!G16 | H32: Raw Value (cross-ref) | I32: Raw measured volume sourced directly from AORA Mass Balance System
E33: Closing % (share) | F33: H | G33: =IF(('Crude Inventory (Live Formulas)'!G16+G17+G18+G19)=0,0,'Crude Inventory (Live Formulas)'!G16/('Crude Inventory (Live Formulas)'!G16+G17+G18+G19)) | H33: IF / Division | I33: Crude's share of tank total closing vol. =0 if tank empty.
A34: 10 | B34: TK17 | C34: IRA | D34: Iracema | E34: Opening Volume (MB) | F34: E | G34: ='Crude Inventory (Live Formulas)'!E17 | H34: Raw Value (cross-ref) | I34: Raw measured volume sourced directly from AORA Mass Balance System
E35: Opening % (share) | F35: F | G35: =IF(('Crude Inventory (Live Formulas)'!E16+E17+E18+E19)=0,0,'Crude Inventory (Live Formulas)'!E17/('Crude Inventory (Live Formulas)'!E16+E17+E18+E19)) | H35: IF / Division | I35: Crude's share of tank total opening vol. =0 if tank empty.
E36: Closing Volume (MB) | F36: G | G36: ='Crude Inventory (Live Formulas)'!G17 | H36: Raw Value (cross-ref) | I36: Raw measured volume sourced directly from AORA Mass Balance System
E37: Closing % (share) | F37: H | G37: =IF(('Crude Inventory (Live Formulas)'!G16+G17+G18+G19)=0,0,'Crude Inventory (Live Formulas)'!G17/('Crude Inventory (Live Formulas)'!G16+G17+G18+G19)) | H37: IF / Division | I37: Crude's share of tank total closing vol. =0 if tank empty.
A38: 11 | B38: TK17 | C38: LUL | D38: Tupi (Lula) | E38: Opening Volume (MB) | F38: E | G38: ='Crude Inventory (Live Formulas)'!E18 | H38: Raw Value (cross-ref) | I38: Raw measured volume sourced directly from AORA Mass Balance System
E39: Opening % (share) | F39: F | G39: =IF(('Crude Inventory (Live Formulas)'!E16+E17+E18+E19)=0,0,'Crude Inventory (Live Formulas)'!E18/('Crude Inventory (Live Formulas)'!E16+E17+E18+E19)) | H39: IF / Division | I39: Crude's share of tank total opening vol. =0 if tank empty.
E40: Closing Volume (MB) | F40: G | G40: ='Crude Inventory (Live Formulas)'!G18 | H40: Raw Value (cross-ref) | I40: Raw measured volume sourced directly from AORA Mass Balance System
...

Sheet Formula Pattern Guide
A1: FORMULA PATTERN GUIDE — Crude Inventory By Tank Report
A2: # | B2: KPI Name | C2: Column | D2: Applied To | E2: Formula Type | F2: Formula Pattern (as written in Excel) | G2: What It Means
A3: 1 | B3: Opening Volume (MB) | C3: E | D3: Crude-level rows | E3: Raw Value | F3: Actual measured volume (no formula — sourced from AORA) | G3: Direct value from AORA Mass Balance System
A4: 2 | B4: Opening % (share) | C4: F | D4: Crude-level rows | E4: IF / Division | F4: =IF((E[r1]+E[r2]+...+E[rN])=0, 0, E[this_row]/(E[r1]+E[r2]+...+E[rN])) | G4: Each crude's % share of tank total opening vol. Guards against divide-by-zero.
A5: 3 | B5: Opening Volume — Total | C5: E | D5: Tank Total row | E5: SUM | F5: =E[r1]+E[r2]+...+E[rN] (single crude: =E[r1]) | G5: Sum of all crude volumes in the tank group
A6: 4 | B6: Opening % — Total | C6: F | D6: Tank Total row | E6: Literal 1 | F6: 1 (literal constant) | G6: Always 100% — sum of all crude shares = 1
A7: 5 | B7: Closing Volume (MB) | C7: G | D7: Crude-level rows | E7: Raw Value | F7: Actual measured volume (no formula — sourced from AORA) | G7: Direct value from AORA Mass Balance System
A8: 6 | B8: Closing % (share) | C8: H | D8: Crude-level rows | E8: IF / Division | F8: =IF((G[r1]+G[r2]+...+G[rN])=0, 0, G[this_row]/(G[r1]+G[r2]+...+G[rN])) | G8: Each crude's % share of tank total closing vol. Guards against divide-by-zero.
A9: 7 | B9: Closing Volume — Total | C9: G | D9: Tank Total row | E9: SUM | F9: =G[r1]+G[r2]+...+G[rN] (single crude: =G[r1]) | G9: Sum of all crude volumes in the tank group
A10: 8 | B10: Closing % — Total | C10: H | D10: Tank Total row | E10: Literal 1 | F10: 1 (literal constant) | G10: Always 100% — sum of all crude shares = 1
A11: 9 | B11: Grand Total — Opening Vol | C11: E | D11: Grand Total row | E11: SUM (all tanks) | F11: =E[crude1]+E[crude2]+...+E[crude_all] | G11: Sum of ALL individual crude rows across ALL tanks
A12: 10 | B12: Grand Total — Closing Vol | C12: G | D12: Grand Total row | E12: SUM (all tanks) | F12: =G[crude1]+G[crude2]+...+G[crude_all] | G12: Sum of ALL individual crude rows across ALL tanks
