Workbook

Sheet Daily Inventory (Live Formulas)
A1: CARSON DAILY INVENTORY REPORT — MPC Carson Refinery | AORA Mass Balance System | Unit: Barrels
A2: # | B2: SAP Code (Table Name) | C2: Full Product Name | D2: Tank | E2: Opening Net Volume (BBLs) | F2: Opening Gravity | G2: Closing Net Volume (BBLs) | H2: Closing Gross Volume (BBLs) | I2: Level Feet | J2: Gravity (Closing) | K2: Temperature | L2: Total Water (BBLs) | M2: BSW Feet | N2: Volume of Available Product | O2: Remaining Capacity | P2: Inventory Change Net Vol (BBLs)
A3: 1. Acc_84Blendgrade — 84 Blendgrade
B4: Acc_84Blendgrade | C4: 84 Blendgrade | D4: LF_001 | E4: 31000 | F4: 57.2 | G4: 31000 | H4: 31000 | I4: 0 | J4: 57.2 | K4: 60 | L4: 0 | M4: 0 | N4: 31000 | O4: 369000 | P4: 0
D5: TK51 | E5: 58320.656 | F5: 60.74 | G5: 58172.037 | H5: 58244.26 | I5: 23.688 | J5: 60.74 | K5: 61.8 | L5: 114.756 | M5: 0.083 | N5: 58172.037 | O5: 341827.96 | P5: -148.619
B6: Acc_84Blendgrade | C6: 84 Blendgrade | D6: Total | E6: =E4+E5 | F6: =AVERAGE(F4,F5) | G6: =G4+G5 | H6: =H4+H5 | J6: =AVERAGE(J4,J5) | L6: =L4+L5 | N6: =N4+N5 | O6: =O4+O5 | P6: =P4+P5
A7: 2. Acc_84RegSuboctane — 84 Regular Suboctane CBG AZ
B8: Acc_84RegSuboctane | C8: 84 Regular Suboctane CBG AZ | D8: TK53 | E8: 19852.175 | F8: 62.802 | G8: 22670.985 | H8: 22639.29 | I8: 9.698 | J8: 62.861 | K8: 58 | L8: 0 | M8: 0 | N8: 22670.985 | O8: 377329.02 | P8: 2818.81
B9: Acc_84RegSuboctane | C9: 84 Regular Suboctane CBG AZ | D9: Total | E9: =E8 | F9: =AVERAGE(F8) | G9: =G8 | H9: =H8 | J9: =AVERAGE(J8) | L9: =L8 | N9: =N8 | O9: =O8 | P9: =P8
A10: 3. Acc_84RegularCARBOB — 84 Regular CARBOB
B11: Acc_84RegularCARBOB | C11: 84 Regular CARBOB | D11: TK41 | E11: 20162.021 | F11: 63.63 | G11: 35374.237 | H11: 35630.42 | I11: 15 | J11: 63.63 | K11: 70.2 | L11: 0 | M11: 0 | N11: 35374.237 | O11: 364625.76 | P11: 15212.216
D12: TK50 | E12: 69258.132 | F12: 62.529 | G12: 46977.937 | H12: 47242.02 | I12: 19.448 | J12: 62.663 | K12: 68 | L12: 0 | M12: 0 | N12: 46977.937 | O12: 353022.06 | P12: -22280.195
D13: TK54 | E13: 28887.496 | F13: 60 | G13: 126527.75 | H13: 127259.49 | I13: 40.875 | J13: 60 | K13: 68.4 | L13: 0 | M13: 0 | N13: 126527.75 | O13: 273472.25 | P13: 97640.252
D14: TK55 | E14: 67838.186 | F14: 62.1 | G14: 76802.676 | H14: 76717.52 | I14: 30.656 | J14: 62.1 | K14: 58.4 | L14: 0 | M14: 0 | N14: 76802.676 | O14: 323197.32 | P14: 8964.49
D15: TK65 | E15: 134787.36 | F15: 62.811 | G15: 134777.4 | H15: 136094.8 | I15: 43.5 | J15: 62.969 | K15: 73.8 | L15: 0 | M15: 0 | N15: 134777.4 | O15: 265222.6 | P15: -9.961
B16: Acc_84RegularCARBOB | C16: 84 Regular CARBOB | D16: Total | E16: =E11+E12+E13+E14+E15 | F16: =AVERAGE(F11,F12,F13,F14,F15) | G16: =G11+G12+G13+G14+G15 | H16: =H11+H12+H13+H14+H15 | J16: =AVERAGE(J11,J12,J13,J14,J15) | L16: =L11+L12+L13+L14+L15 | N16: =N11+N12+N13+N14+N15 | O16: =O11+O12+O13+O14+O15 | P16: =P11+P12+P13+P14+P15
A17: 4. Acc_89PremiumCARB — 89 Premium CARBOB
B18: Acc_89PremiumCARB | C18: 89 Premium CARBOB | D18: TK45 | E18: 79736.396 | F18: 65.44 | G18: 32836.07 | H18: 32939.5 | I18: 13.469 | J18: 65.44 | K18: 64.4 | L18: 0 | M18: 0 | N18: 32836.07 | O18: 367163.93 | P18: -46900.326
D19: TK52 | E19: 93417.766 | F19: 68.276 | G19: 97386.345 | H19: 98048.17 | I19: 38.896 | J19: 68.915 | K19: 69.2 | L19: 0 | M19: 0 | N19: 97386.345 | O19: 302613.66 | P19: 3968.579
B20: Acc_89PremiumCARB | C20: 89 Premium CARBOB | D20: Total | E20: =E18+E19 | F20: =AVERAGE(F18,F19) | G20: =G18+G19 | H20: =H18+H19 | J20: =AVERAGE(J18,J19) | L20: =L18+L19 | N20: =N18+N19 | O20: =O18+O19 | P20: =P18+P19
A21: 5. Acc_AlkyFeed — Alky Feed
B22: Acc_AlkyFeed | C22: Alky Feed | D22: TK682 | E22: 10397.41 | F22: 112 | G22: 10417.07 | H22: 10417.07 | I22: 26.854 | J22: 112 | K22: 65.8 | L22: 0 | M22: 0 | N22: 10417.07 | O22: 389582.93 | P22: 19.66
D23: TK76 | E23: 15837.625 | F23: 110 | G23: 18808.709 | H23: 18808.709 | I23: 0 | J23: 110 | K23: 76.924 | L23: 0 | M23: 0 | N23: 18808.709 | O23: 381191.29 | P23: 2971.084
D24: TK78 | E24: 4192.393 | F24: 107.76 | G24: 3792.62 | H24: 3792.62 | I24: 0 | J24: 107.76 | K24: 74.445 | L24: 0 | M24: 0 | N24: 3792.62 | O24: 396207.38 | P24: -399.773
B25: Acc_AlkyFeed | C25: Alky Feed | D25: Total | E25: =E22+E23+E24 | F25: =AVERAGE(F22,F23,F24) | G25: =G22+G23+G24 | H25: =H22+H23+H24 | J25: =AVERAGE(J22,J23,J24) | L25: =L22+L23+L24 | N25: =N22+N23+N24 | O25: =O22+O23+O24 | P25: =P22+P23+P24
A26: 6. Acc_Alkylate — Alkylate
B27: Acc_Alkylate | C27: Alkylate | D27: LF_005 | E27: 26000 | F27: 70 | G27: 26000 | H27: 26000 | I27: 0 | J27: 70 | K27: 60 | L27: 0 | M27: 0 | N27: 26000 | O27: 374000 | P27: 0
D28: TK31 | E28: 15330.008 | F28: 69.8 | G28: 19287.735 | H28: 19419.79 | I28: 10.708 | J28: 69.8 | K28: 69.2 | L28: 0 | M28: 0 | N28: 19287.735 | O28: 380712.27 | P28: 3957.727
D29: TK43 | E29: 52824.822 | F29: 66 | G29: 52819.057 | H29: 52864.52 | I29: 27.531 | J29: 66 | K29: 61.2 | L29: 0 | M29: 0 | N29: 52819.057 | O29: 347180.94 | P29: -5.765
D30: TK64 | E30: 33416.721 | F30: 67.8 | G30: 27828.114 | H30: 28235.84 | I30: 11.542 | J30: 67.8 | K30: 79.8 | L30: 0 | M30: 0 | N30: 27828.114 | O30: 372171.89 | P30: -5588.607
B31: Acc_Alkylate | C31: Alkylate | D31: Total | E31: =E27+E28+E29+E30 | F31: =AVERAGE(F27,F28,F29,F30) | G31: =G27+G28+G29+G30 | H31: =H27+H28+H29+H30 | J31: =AVERAGE(J27,J28,J29,J30) | L31: =L27+L28+L29+L30 | N31: =N27+N28+N29+N30 | O31: =O27+O28+O29+O30 | P31: =P27+P28+P29+P30
A32: 7. Acc_ChemPropylene — Chemical Grade Propylene
B33: Acc_ChemPropylene | C33: Chemical Grade Propylene | D33: TK398 | E33: 2035.89 | F33: 139.21 | G33: 2908.52 | H33: 2908.52 | I33: 18.778 | J33: 139.21 | K33: 66.227 | L33: 0 | M33: 0 | N33: 2908.52 | O33: 397091.48 | P33: 872.63
D34: TK399 | E34: 3794.26 | F34: 139.16 | G34: 4808.09 | H34: 4808.09 | I34: 26.619 | J34: 139.16 | K34: 66.813 | L34: 0 | M34: 0 | N34: 4808.09 | O34: 395191.91 | P34: 1013.83
B35: Acc_ChemPropylene | C35: Chemical Grade Propylene | D35: Total | E35: =E33+E34 | F35: =AVERAGE(F33,F34) | G35: =G33+G34 | H35: =H33+H34 | J35: =AVERAGE(J33,J34) | L35: =L33+L34 | N35: =N33+N34 | O35: =O33+O34 | P35: =P33+P34
A36: 8. Acc_Crude — Crude Mix
B37: Acc_Crude | C37: Crude Mix | D37: LF_004 | E37: 49000 | F37: 27 | G37: 49000 | H37: 49000 | I37: 0 | J37: 27 | K37: 60 | L37: 0 | M37: 0 | N37: 49000 | O37: 351000 | P37: 0
D38: TK13 | E38: 396563.69 | F38: 30.79 | G38: 339634.7 | H38: 337575.49 | I38: 46.354 | J38: 30.79 | K38: 46.4 | L38: 140.308 | M38: 0.083 | N38: 339634.7 | O38: 60365.3 | P38: -56928.991
D39: TK16 | E39: 80291.347 | F39: 29.7 | G39: 55214.268 | H39: 55386.52 | I39: 27.385 | J39: 29.7 | K39: 67 | L39: 0 | M39: 0 | N39: 55214.268 | O39: 344785.73 | P39: -25077.079
D40: TK17 | E40: 80983.897 | F40: 29.7 | G40: 56679.328 | H40: 57014 | I40: 28.375 | J40: 29.7 | K40: 73.2 | L40: 0 | M40: 0 | N40: 56679.328 | O40: 343320.67 | P40: -24304.569
...

Sheet KPI-Table-Formula Reference
A1: KPI · TABLE · FORMULA REFERENCE — Formulas are live (click a cell → see formula in fx bar)
A2: Legend: ■ GREEN cell = SUM formula ■ YELLOW cell = AVERAGE formula ■ GREY cell = Raw Data (no aggregation) Click any formula cell → formula appears in fx bar above
A3: # | B3: SAP Code (Table Name) | C3: Full Product Name | D3: KPI Name | E3: KPI Col | F3: Formula (Live — shown in fx bar) | G3: Formula Type | H3: Tanks in Group
A4: 1 | B4: Acc_84Blendgrade | C4: 84 Blendgrade | D4: Opening Net Volume (BBLs) | E4: E | F4: ='Daily Inventory (Live Formulas)'!E4+'Daily Inventory (Live Formulas)'!E5 | G4: SUM | H4: LF_001, TK51
D5: Opening Gravity | E5: F | F5: =AVERAGE('Daily Inventory (Live Formulas)'!F4,'Daily Inventory (Live Formulas)'!F5) | G5: AVERAGE
D6: Closing Net Volume (BBLs) | E6: G | F6: ='Daily Inventory (Live Formulas)'!G4+'Daily Inventory (Live Formulas)'!G5 | G6: SUM
D7: Closing Gross Volume (BBLs) | E7: H | F7: ='Daily Inventory (Live Formulas)'!H4+'Daily Inventory (Live Formulas)'!H5 | G7: SUM
D8: Level Feet | E8: I | F8: ="'Daily Inventory (Live Formulas)'!I4 — Raw data, no formula" | G8: Raw Data
D9: Gravity (Closing) | E9: J | F9: =AVERAGE('Daily Inventory (Live Formulas)'!J4,'Daily Inventory (Live Formulas)'!J5) | G9: AVERAGE
D10: Temperature | E10: K | F10: ="'Daily Inventory (Live Formulas)'!K4 — Raw data, no formula" | G10: Raw Data
D11: Total Water (BBLs) | E11: L | F11: ='Daily Inventory (Live Formulas)'!L4+'Daily Inventory (Live Formulas)'!L5 | G11: SUM
D12: BSW Feet | E12: M | F12: ="'Daily Inventory (Live Formulas)'!M4 — Raw data, no formula" | G12: Raw Data
D13: Volume of Available Product (BBLs) | E13: N | F13: ='Daily Inventory (Live Formulas)'!N4+'Daily Inventory (Live Formulas)'!N5 | G13: SUM
D14: Remaining Capacity (BBLs) | E14: O | F14: ='Daily Inventory (Live Formulas)'!O4+'Daily Inventory (Live Formulas)'!O5 | G14: SUM
D15: Inventory Change Net Vol (BBLs) | E15: P | F15: ='Daily Inventory (Live Formulas)'!P4+'Daily Inventory (Live Formulas)'!P5 | G15: SUM
A16: 2 | B16: Acc_84RegSuboctane | C16: 84 Regular Suboctane CBG AZ | D16: Opening Net Volume (BBLs) | E16: E | F16: ='Daily Inventory (Live Formulas)'!E8 | G16: SUM | H16: TK53
D17: Opening Gravity | E17: F | F17: =AVERAGE('Daily Inventory (Live Formulas)'!F8) | G17: AVERAGE
D18: Closing Net Volume (BBLs) | E18: G | F18: ='Daily Inventory (Live Formulas)'!G8 | G18: SUM
D19: Closing Gross Volume (BBLs) | E19: H | F19: ='Daily Inventory (Live Formulas)'!H8 | G19: SUM
D20: Level Feet | E20: I | F20: ="'Daily Inventory (Live Formulas)'!I8 — Raw data, no formula" | G20: Raw Data
D21: Gravity (Closing) | E21: J | F21: =AVERAGE('Daily Inventory (Live Formulas)'!J8) | G21: AVERAGE
D22: Temperature | E22: K | F22: ="'Daily Inventory (Live Formulas)'!K8 — Raw data, no formula" | G22: Raw Data
D23: Total Water (BBLs) | E23: L | F23: ='Daily Inventory (Live Formulas)'!L8 | G23: SUM
D24: BSW Feet | E24: M | F24: ="'Daily Inventory (Live Formulas)'!M8 — Raw data, no formula" | G24: Raw Data
D25: Volume of Available Product (BBLs) | E25: N | F25: ='Daily Inventory (Live Formulas)'!N8 | G25: SUM
D26: Remaining Capacity (BBLs) | E26: O | F26: ='Daily Inventory (Live Formulas)'!O8 | G26: SUM
D27: Inventory Change Net Vol (BBLs) | E27: P | F27: ='Daily Inventory (Live Formulas)'!P8 | G27: SUM
A28: 3 | B28: Acc_84RegularCARBOB | C28: 84 Regular CARBOB | D28: Opening Net Volume (BBLs) | E28: E | F28: ='Daily Inventory (Live Formulas)'!E11+'Daily Inventory (Live Formulas)'!E12+'Daily Inventory (Live Formulas)'!E13+'Daily Inventory (Live Formulas)'!E14+'Daily Inventory (Live Formulas)'!E15 | G28: SUM | H28: TK41, TK50, TK54, TK55, TK65
D29: Opening Gravity | E29: F | F29: =AVERAGE('Daily Inventory (Live Formulas)'!F11,'Daily Inventory (Live Formulas)'!F12,'Daily Inventory (Live Formulas)'!F13,'Daily Inventory (Live Formulas)'!F14,'Daily Inventory (Live Formulas)'!F15) | G29: AVERAGE
D30: Closing Net Volume (BBLs) | E30: G | F30: ='Daily Inventory (Live Formulas)'!G11+'Daily Inventory (Live Formulas)'!G12+'Daily Inventory (Live Formulas)'!G13+'Daily Inventory (Live Formulas)'!G14+'Daily Inventory (Live Formulas)'!G15 | G30: SUM
D31: Closing Gross Volume (BBLs) | E31: H | F31: ='Daily Inventory (Live Formulas)'!H11+'Daily Inventory (Live Formulas)'!H12+'Daily Inventory (Live Formulas)'!H13+'Daily Inventory (Live Formulas)'!H14+'Daily Inventory (Live Formulas)'!H15 | G31: SUM
D32: Level Feet | E32: I | F32: ="'Daily Inventory (Live Formulas)'!I11 — Raw data, no formula" | G32: Raw Data
D33: Gravity (Closing) | E33: J | F33: =AVERAGE('Daily Inventory (Live Formulas)'!J11,'Daily Inventory (Live Formulas)'!J12,'Daily Inventory (Live Formulas)'!J13,'Daily Inventory (Live Formulas)'!J14,'Daily Inventory (Live Formulas)'!J15) | G33: AVERAGE
D34: Temperature | E34: K | F34: ="'Daily Inventory (Live Formulas)'!K11 — Raw data, no formula" | G34: Raw Data
D35: Total Water (BBLs) | E35: L | F35: ='Daily Inventory (Live Formulas)'!L11+'Daily Inventory (Live Formulas)'!L12+'Daily Inventory (Live Formulas)'!L13+'Daily Inventory (Live Formulas)'!L14+'Daily Inventory (Live Formulas)'!L15 | G35: SUM
D36: BSW Feet | E36: M | F36: ="'Daily Inventory (Live Formulas)'!M11 — Raw data, no formula" | G36: Raw Data
D37: Volume of Available Product (BBLs) | E37: N | F37: ='Daily Inventory (Live Formulas)'!N11+'Daily Inventory (Live Formulas)'!N12+'Daily Inventory (Live Formulas)'!N13+'Daily Inventory (Live Formulas)'!N14+'Daily Inventory (Live Formulas)'!N15 | G37: SUM
D38: Remaining Capacity (BBLs) | E38: O | F38: ='Daily Inventory (Live Formulas)'!O11+'Daily Inventory (Live Formulas)'!O12+'Daily Inventory (Live Formulas)'!O13+'Daily Inventory (Live Formulas)'!O14+'Daily Inventory (Live Formulas)'!O15 | G38: SUM
D39: Inventory Change Net Vol (BBLs) | E39: P | F39: ='Daily Inventory (Live Formulas)'!P11+'Daily Inventory (Live Formulas)'!P12+'Daily Inventory (Live Formulas)'!P13+'Daily Inventory (Live Formulas)'!P14+'Daily Inventory (Live Formulas)'!P15 | G39: SUM
A40: 4 | B40: Acc_89PremiumCARB | C40: 89 Premium CARBOB | D40: Opening Net Volume (BBLs) | E40: E | F40: ='Daily Inventory (Live Formulas)'!E18+'Daily Inventory (Live Formulas)'!E19 | G40: SUM | H40: TK45, TK52
...

Sheet Formula Pattern Guide
A1: FORMULA PATTERN GUIDE — How Each KPI Total is Calculated
A2: # | B2: KPI Name | C2: Column | D2: Formula Type | E2: Formula Pattern (as written in Excel) | F2: Example — 3 tanks
A3: 1 | B3: Opening Net Volume (BBLs) | C3: E | D3: SUM | E3: =E[row1]+E[row2]+...+E[rowN] | F3: =E4+E5+E6
A4: 2 | B4: Opening Gravity | C4: F | D4: AVERAGE | E4: =AVERAGE(F[row1],F[row2],...,F[rowN]) | F4: =AVERAGE(F4,F5,F6)
A5: 3 | B5: Closing Net Volume (BBLs) | C5: G | D5: SUM | E5: =G[row1]+G[row2]+...+G[rowN] | F5: =G4+G5+G6
A6: 4 | B6: Closing Gross Volume (BBLs) | C6: H | D6: SUM | E6: =H[row1]+H[row2]+...+H[rowN] | F6: =H4+H5+H6
A7: 5 | B7: Level Feet | C7: I | D7: Raw Data | E7: No formula in Total row | F7: Individual tank reading only
A8: 6 | B8: Gravity (Closing) | C8: J | D8: AVERAGE | E8: =AVERAGE(J[row1],J[row2],...,J[rowN]) | F8: =AVERAGE(J4,J5,J6)
A9: 7 | B9: Temperature | C9: K | D9: Raw Data | E9: No formula in Total row | F9: Individual tank reading only
A10: 8 | B10: Total Water (BBLs) | C10: L | D10: SUM | E10: =L[row1]+L[row2]+...+L[rowN] | F10: =L4+L5+L6
A11: 9 | B11: BSW Feet | C11: M | D11: Raw Data | E11: No formula in Total row | F11: Individual tank reading only
A12: 10 | B12: Volume of Available Product (BBLs) | C12: N | D12: SUM | E12: =N[row1]+N[row2]+...+N[rowN] | F12: =N4+N5+N6
A13: 11 | B13: Remaining Capacity (BBLs) | C13: O | D13: SUM | E13: =O[row1]+O[row2]+...+O[rowN] | F13: =O4+O5+O6
A14: 12 | B14: Inventory Change Net Vol (BBLs) | C14: P | D14: SUM | E14: =P[row1]+P[row2]+...+P[rowN] | F14: =P4+P5+P6
